Workbook

Sheet CLIENTES
D2: 78812768
A3: 13 | B3: CABRERA, Olga (Oeste II) | C3: =VLOOKUP(A3,'Hoja 16'!$A$1:$C$813,3,FALSE) -> El eter Sebastian | D3: 110651
A4: 17 | B4: BRUNO, Mayra (Alderetes) | C4: =VLOOKUP(A4,'Hoja 16'!$A$1:$C$813,3,FALSE) -> Brandan Julio | D4: -348
A5: 18 | B5: AUAD, Mariana (Oeste II) | C5: =VLOOKUP(A5,'Hoja 16'!$A$1:$C$813,3,FALSE) -> El eter Sebastian | D5: 1217762
D6: 8300
A7: 27 | B7: CORDOBA, David (Jujuy) | C7: =VLOOKUP(A7,'Hoja 16'!$A$1:$C$813,3,FALSE) -> Brandan Julio | D7: 2800153
A8: 28 | B8: ALVARADO, Julio (Jujuy) | C8: =VLOOKUP(A8,'Hoja 16'!$A$1:$C$813,3,FALSE) -> Brandan Julio | D8: -207025
A9: 34 | B9: AMADO, Graciela (Lules) | C9: =VLOOKUP(A9,'Hoja 16'!$A$1:$C$813,3,FALSE) -> Brandan Julio | D9: 239405
A10: 37 | B10: ESQUENDEFE, Joaquin (Simoca) | C10: =VLOOKUP(A10,'Hoja 16'!$A$1:$C$813,3,FALSE) -> BRIAN | D10: 0
D11: 199210
A12: 40 | B12: ANDRADES ( Este) | C12: =VLOOKUP(A12,'Hoja 16'!$A$1:$C$813,3,FALSE) -> Veliz Marcelo | D12: 3058530
A13: 43 | B13: ANTA, Margarita (Jujuy) | C13: =VLOOKUP(A13,'Hoja 16'!$A$1:$C$813,3,FALSE) -> Brandan Julio | D13: 45689
A14: 52 | B14: ARON, David (Lules) | C14: =VLOOKUP(A14,'Hoja 16'!$A$1:$C$813,3,FALSE) -> veliz Marcelo | D14: -8095
A15: 58 | B15: ARTAZA, Romina (Ciudadela) | C15: =VLOOKUP(A15,'Hoja 16'!$A$1:$C$813,3,FALSE) -> Brandan Julio | D15: 125381
A16: 65 | B16: AVILA, Sergio (157) | C16: =VLOOKUP(A16,'Hoja 16'!$A$1:$C$813,3,FALSE) -> Veliz Marcelo | D16: 1289830
A17: 68 | B17: AVILA, Dolores (Jujuy) | C17: =VLOOKUP(A17,'Hoja 16'!$A$1:$C$813,3,FALSE) -> El eter Sebastian | D17: 201408
A18: 72 | B18: CASERES, Maria (Centro) | C18: =VLOOKUP(A18,'Hoja 16'!$A$1:$C$813,3,FALSE) -> Veliz Marcelo | D18: 0
A19: 73 | B19: BALBOA, Roque (157) | C19: =VLOOKUP(A19,'Hoja 16'!$A$1:$C$813,3,FALSE) -> Veliz Marcelo | D19: 608084
A20: 74 | B20: BALCEDA, Fabiana (Oeste II) | C20: =VLOOKUP(A20,'Hoja 16'!$A$1:$C$813,3,FALSE) -> El eter Sebastian | D20: 0
A21: 82 | B21: QUIPILDOR MIGUEL (LEALES) | C21: =VLOOKUP(A21,'Hoja 16'!$A$1:$C$813,3,FALSE) -> Veliz Marcelo | D21: 419284
A22: 86 | B22: BEJAS, Diego (Centro) | C22: =VLOOKUP(A22,'Hoja 16'!$A$1:$C$813,3,FALSE) -> El eter Sebastian | D22: 718100
A23: 87 | B23: BEJAS, Matias (Oeste II) | C23: =VLOOKUP(A23,'Hoja 16'!$A$1:$C$813,3,FALSE) -> El eter Sebastian | D23: 366048
... A25: 96 | B25: SUPER TANIA (Concepci¾n) | C25: =VLOOKUP(A25,'Hoja 16'!$A$1:$C$813,3,FALSE) -> BRIAN | D25: 50
D26: 42676
A27: 102 | B27: BRABE, Manuel (Lules) | C27: =VLOOKUP(A27,'Hoja 16'!$A$1:$C$813,3,FALSE) -> Brandan Julio | D27: 57825
A28: 103 | B28: BRAIN, Hugo (Famaillß) | C28: =VLOOKUP(A28,'Hoja 16'!$A$1:$C$813,3,FALSE) -> Veliz Marcelo | D28: 0
A29: 109 | B29: BRITO, Brahian (157) | C29: =VLOOKUP(A29,'Hoja 16'!$A$1:$C$813,3,FALSE) -> Veliz Marcelo | D29: 372445
A30: 114 | B30: BRIZUELA, Fabian (Ciudadela) | C30: =VLOOKUP(A30,'Hoja 16'!$A$1:$C$813,3,FALSE) -> Brandan Julio | D30: 90163
A31: 119 | B31: BUSTOS, Cesar (Banda) | C31: =VLOOKUP(A31,'Hoja 16'!$A$1:$C$813,3,FALSE) -> El eter Sebastian | D31: 299394
A32: 121 | B32: BUSTOS, Javier (Villa) | C32: =VLOOKUP(A32,'Hoja 16'!$A$1:$C$813,3,FALSE) -> El eter Sebastian | D32: 768971
A33: 122 | B33: BUSTOS, Luis (Banda) | C33: =VLOOKUP(A33,'Hoja 16'!$A$1:$C$813,3,FALSE) -> Veliz Marcelo | D33: 621674
A34: 123 | B34: BUSTOS, Maria (Banda) | C34: =VLOOKUP(A34,'Hoja 16'!$A$1:$C$813,3,FALSE) -> El eter Sebastian | D34: 375498
A35: 124 | B35: BUSTOS, Roberto (Banda) | C35: =VLOOKUP(A35,'Hoja 16'!$A$1:$C$813,3,FALSE) -> Veliz Marcelo | D35: 242704
A36: 125 | B36: BUSTOS, Sebastißn (Este) | C36: =VLOOKUP(A36,'Hoja 16'!$A$1:$C$813,3,FALSE) -> El eter Sebastian | D36: 1731744
A37: 126 | B37: BUSTOS, Denisse (Banda) | C37: =VLOOKUP(A37,'Hoja 16'!$A$1:$C$813,3,FALSE) -> El eter Sebastian | D37: 383032
A38: 139 | B38: CAJCHAYA, Pina (Jujuy) | C38: =VLOOKUP(A38,'Hoja 16'!$A$1:$C$813,3,FALSE) -> Brandan Julio | D38: 0
A39: 148 | B39: SORIA, Rosario (Y. B.) | C39: =VLOOKUP(A39,'Hoja 16'!$A$1:$C$813,3,FALSE) -> Brandan Julio | D39: 116247
D40: 25000
A41: 156 | B41: BRANDAN, Maria Laura (Banda) | C41: =VLOOKUP(A41,'Hoja 16'!$A$1:$C$813,3,FALSE) -> El eter Sebastian | D41: 0
D42: 0
...

Sheet Hoja 16
A1: 818 | B1: 12 | C1: BRIAN
A2: 1009 | B2: 12 | C2: BRIAN
A3: 943 | B3: 12 | C3: BRIAN
A4: 1032 | B4: 12 | C4: BRIAN
A5: 1035 | B5: 12 | C5: BRIAN
A6: 699 | B6: 12 | C6: BRIAN
A7: 712 | B7: 12 | C7: BRIAN
A8: 941 | B8: 12 | C8: BRIAN
A9: 405 | B9: 12 | C9: BRIAN
A10: 996 | B10: 12 | C10: BRIAN
A11: 926 | B11: 12 | C11: BRIAN
A12: 1043 | B12: 12 | C12: BRIAN
... A419: 978 | B419: 3 | C419: Veliz Marcelo
A420: #N/A | B420: 4 | C420: Brandan Julio
A421: #N/A | B421: 4 | C421: Brandan Julio
A422: #N/A | B422: 4 | C422: Brandan Julio
A423: #N/A | B423: 4 | C423: Brandan Julio
A424: #N/A | B424: 4 | C424: Brandan Julio
A425: #N/A | B425: 4 | C425: Brandan Julio
A426: #N/A | B426: 4 | C426: Brandan Julio
A427: 910 | B427: 2 | C427: El eter Sebastian
A428: 63 | B428: 2 | C428: El eter Sebastian
A429: 300 | B429: 4 | C429: Brandan Julio
A430: 452 | B430: 4 | C430: Brandan Julio
A431: 507 | B431: 3 | C431: Veliz Marcelo
A432: 501 | B432: 2 | C432: El eter Sebastian
A433: 606 | B433: 2 | C433: El eter Sebastian
A434: 54 | B434: 2 | C434: El eter Sebastian
A435: 379 | B435: 2 | C435: El eter Sebastian
A436: 503 | B436: 2 | C436: El eter Sebastian
A437: 145 | B437: 2 | C437: El eter Sebastian
A438: 159 | B438: 2 | C438: El eter Sebastian
... A663: 1063 | B663: 2 | C663: El eter Sebastian
A664: #N/A | B664: 2 | C664: El eter Sebastian
A665: #N/A | B665: 4 | C665: Brandan Julio
A666: 865 | B666: 2 | C666: El eter Sebastian
A667: 609 | B667: 4 | C667: Brandan Julio
A668: 1016 | B668: 4 | C668: Brandan Julio
A669: 936 | B669: 12 | C669: BRIAN
A670: 760 | B670: 2 | C670: El eter Sebastian
...

Sheet SISTEMA
A1: CUENTA CORRIENTE CLIENTES JUNIO 2026 - SISTEMA
A2: CODIGO | B2: VENDEDOR | C2: NOMBRE | D2: SALDO
A3: 1 | B3: ANDREA | C3: CONSUMIDOR FINAL | D3: $ 270,088,047.01
A4: 919 | B4: BRIAN | C4: ARGAÐARAZ, Susana (Alberdi) | D4: $ 3.41
A5: 13 | B5: El eter Sebastian | C5: CABRERA, Olga (Oeste II) | D5: $ 0.87
A6: 17 | B6: Brandan Julio | C6: BRUNO, Mayra (Alderetes) | D6: -$ 348.32
A7: 18 | B7: El eter Sebastian | C7: AUAD, Mariana (Oeste II) | D7: $ 999,149.09
A8: 25 | B8: ANDREA | C8: MANOLO | D8: $ 20,760.00
A9: 27 | B9: Brandan Julio | C9: CORDOBA, David (Jujuy) | D9: $ 1,707,024.49
A10: 28 | B10: Brandan Julio | C10: ALVARADO, Julio (Jujuy) | D10: $ 0.00
A11: 29 | B11: El eter Sebastian | C11: ALVARADO, Olga (Banda) | D11: $ 111,604.31
A12: 34 | B12: Brandan Julio | C12: AMADO, Graciela (Lules) | D12: $ 231,396.74
A13: 8 | B13: BRIAN | C13: AUTOSERVICIO V Y H (LEON ROUGES) | D13: $ 252,675.62
A14: 39 | B14: ANDREA | C14: ANDRADE LUIS | D14: $ 199,210.08
... A140: 472 | B140: Veliz Marcelo | C140: MARRADES, Benito (Leales) | D140: -$ 598.71
A141: 473 | B141: ANDREA | C141: MAURO (BANDA) | D141: $ 46,670.80 | I141: ,
A142: 474 | B142: Brandan Julio | C142: MARTIN, Marcelo (Y. B) | D142: $ 436,764.34
A143: 476 | B143: Brandan Julio | C143: MARTINEZ, JosÚ (Y. B.) | D143: $ 110,556.28
A144: 477 | B144: veliz Marcelo | C144: LUNA, Diana (Lules) | D144: $ 372,014.86
A145: 478 | B145: Brandan Julio | C145: SARAVIA, Laura (Oeste II) | D145: $ 311,275.39
A146: 483 | B146: ANDREA | C146: MATIAS | D146: $ 2,976.32
A147: 485 | B147: veliz Marcelo | C147: MAZZONE, Maria (Lules) | D147: $ 51,295.22
A148: 487 | B148: Brandan Julio | C148: MEDINA DORA (Jujuy) | D148: $ 1.70
A149: 495 | B149: ANDREA | C149: GRAMAJO, Laura (Monteros) | D149: $ 253,871.26
A150: 496 | B150: Veliz Marcelo | C150: MEJIAS, Nestor (Alderetes) | D150: $ 664,151.60
A151: 502 | B151: ANDREA | C151: PEPE OBRA | D151: $ 20,584.38
A152: 215 | B152: BRIAN | C152: DARWICH, Mariela (Sur) | D152: $ 532,638.40
A153: 522 | B153: Veliz Marcelo | C153: BUSTOS, Rafael (La Florida) | D153: $ 854,047.83
... A300: 1246 | B300: El eter Sebastian | C300: GIACOSA Y CIA SRL | D300: $ 198,479.13

Sheet JULIO
A1: JULIO CTA CTE 01/4
A2: FECHA | B2: CLIENTE | C2: SDO S/ CARP | D2: SDO S/ SIST | E2: DIF | H2: CLIENTE | I2: SDO S/ sist | J2: s/ carp | K2: dif
A3: 46157 | B3: CANO ALEJANDRA | C3: 29476
A4: 46184 | B4: CANO ALEJANDRA | C4: 75875
A5: 46177 | B5: CANO ALEJANDRA | C5: 75753
A6: 46189 | B6: SARAVIA LAURA | C6: =811275-500000 -> 311275
A7: 46189 | B7: BRABE MANUEL | C7: 214375
A8: 46190 | B8: CORDOBA DAVID | C8: 1707024
A9: 46190 | B9: PEDRAZA SERGIO | C9: 417238
A10: 46190 | B10: PEREZ HERNAN | C10: 669689
A11: 46191 | B11: MANTARAS MARIANO | C11: 476378
A12: 46191 | B12: FERNANDEZ DANIEL | C12: 233308
A13: 46195 | B13: GONZALEZ GONZALO | C13: 811277
A14: 46195 | B14: MARTIN MARCELO | C14: 437583
A15: 46195 | B15: MARTINEZ JOSE | C15: 110556
A16: 46195 | B16: SORIA ROSARIO | C16: 199274
A17: 46195 | B17: VELEZ MARCOS | C17: 400874
A18: 46195 | B18: FORRAJERIA GRAMAJO | C18: 232722
A19: 46195 | B19: SILVA PATRICIA | C19: 102394
A20: 46196 | B20: COCO FORRAJERIA | C20: =1024562-15435 -> 1009127
A21: 46196 | B21: VILLALBA IRIS | C21: =5542923-2509700 -> 3033223
A22: 46197 | B22: DARIUS DARIO | C22: 113426
A23: 46197 | B23: GONZALEZ MARIA CRISTINA | C23: 427706
A24: 46197 | B24: OVIEDO PABLO | C24: 655322
A25: 46197 | B25: PAZ VANESA | C25: 867550
A26: 46197 | B26: SEGUER VIVIANA | C26: 949345
A27: 46199 | B27: COSTILLA CLAUDIA | C27: 309358
A28: 46199 | B28: FORRAJERIA MATEO | C28: =877953-400000 -> 477953
A29: 46199 | B29: PAZ MARIA | C29: 1089907
A30: 46199 | B30: REYNOSO ROBERTO | C30: 2682511
A31: 46200 | B31: FILGUEIRAS MARIA | C31: 222089
A32: 46200 | B32: FORRAJERIA CHOC | C32: 260202
A33: 46200 | B33: MARTIN FACUNDO | C33: =602165-5368 -> 596797
A34: 46200 | B34: DISTRI CANIN | C34: 133108
A35: 46200 | B35: REYNOSO ROBERTO | C35: 122250
A36: 46202 | B36: CORDOBA MARCELO | C36: 815374
A37: 46202 | B37: FORRAJERIA ORDOÑEZ | C37: 1072874
A38: 46202 | B38: RUIZ MARIA | C38: 662663
A39: 46202 | B39: AMADO GRACIELA | C39: 231396
A40: 46202 | B40: CORDOBA CARLOS | C40: 585677
...

Sheet MARCELO
A1: MARCELO CTA CTE 30/05
A2: FECHA | B2: CLIENTE | C2: SDO S/ CARP | D2: SDO S/ SIST | E2: DIF
A3: 46142 | B3: SALVATIERRA ROMINA | C3: -49127
A4: 46347 | B4: SARACHO JONATHAN | C4: -8858
A5: 46178 | B5: ROSEDO GUILLERMO | C5: 676408
A6: 46186 | B6: GOMEZ MAXI | C6: 155447
A7: 46189 | B7: MAZZONE MARIA | C7: =106295-55000 -> 51295
A8: 46189 | B8: PEREZ PEDRO | C8: 640801
A9: 46191 | B9: ANDRADES | C9: =2788056-1294382-29261 -> 1464413
A10: 46191 | B10: DIAZ ALFREDO | C10: 2326347
A11: 46191 | B11: NARCHER PAMELA | C11: =994837-17556 -> 977281
A12: 46191 | B12: BUSTOS RAFAEL | C12: 853982
A13: 46192 | B13: DIAZ ARIEL | C13: 1036537
A14: 46192 | B14: GONZALEZ FACUNDO | C14: 667228
A15: 46192 | B15: LOBO IGNACIO | C15: 426370
A16: 46192 | B16: ARRIETA YAQUELIN | C16: 460926
A17: 46192 | B17: AUN NICOLAS | C17: 1429293
A18: 46192 | B18: LOGARZO JOSE | C18: 1786964
A19: 46192 | B19: LOGARZO JOSE | C19: 46875
A20: 46192 | B20: LUNA DIANA | C20: 106869
A21: 46195 | B21: AVILA SERGIO | C21: 1290378
A22: 46195 | B22: BALBOA ROQUE | C22: 610670
A23: 46195 | B23: BRITO BRAHIAN | C23: 791640
... A33: 46198 | B33: URUEÑA FRANCISCO | C33: 555236
A34: 46198 | B34: MONTERO FERNANDO | C34: =396427-250000 -> 146427
A35: 46198 | B35: FIGUEROA ENZO | C35: 320226
A36: 46198 | B36: OBEID LAUTARO | C36: 3392609
A37: 46198 | B37: RENGEL FERNANDO | C37: 158025
A38: 46198 | B38: BUSTOS LUIS | C38: 912533
A39: 46198 | B39: BUSTOS ROBERTO | C39: 262745
A40: 46199 | B40: DANDE MARIA | C40: 259433
A41: 46199 | B41: DECIMA DIEGO | C41: 236994
A42: 46199 | B42: IBAÑEZ NANCY | C42: 949130
A43: 46196 | B43: ROSEDO GUILLERMO | C43: 67640
A44: 46199 | B44: MEJIAS NESTOR | C44: 664151
A45: 46199 | B45: LOPEZ JAVIER | C45: 125275
A46: 46199 | B46: ARRIETA YAQUELIN | C46: 148500
A47: 46199 | B47: OLIVARES LUIS | C47: 431598
A48: 46200 | B48: JACOBO ALVARO | C48: =3216965-2500000 -> 716965
A49: 46200 | B49: GOMEZ MAXI | C49: 15544
...

Sheet ANDREA
A1: ANDREA CTA CTE 30/5
A2: FECHA | B2: CLIENTE | C2: SALDO
A3: 2*/05 | B3: ANDRADES | C3: 199210
A4: 46171 | B4: ANTONELLA | C4: 28947
A5: 46155 | B5: ANTONIO | C5: 57052
A6: 46163 | B6: BRIAN | C6: 48251
A7: 46160 | B7: DANIEL | C7: 101413
A8: 46169 | B8: DANTE | C8: 41756
A9: 46084 | B9: FEDERICO ORDOÑEZ | C9: 220200
A10: 46122 | B10: FEDERICO ORDOÑEZ | C10: 246000
A11: 46171 | B11: GIULIANO | C11: 193521
A12: 46150 | B12: GRAMAJO LAURA | C12: 40621
A13: 46157 | B13: GUSTAVO | C13: 470162
A14: 46161 | B14: GUSTAVO | C14: 19858
A15: 46164 | B15: GUSTAVO | C15: 1430352
... A24: 46171 | B24: RODRIGO | C24: 609272
A25: 46150 | B25: RUIZ NADIA | C25: =419296-10802 -> 408494
A26: 46171 | B26: SEBA | C26: 33661
A27: 46171 | B27: SERGIO | C27: 54076
A28: 46171 | B28: SUAREZ LUIS | C28: 19854
A29: 46171 | B29: SUSANA | C29: 53540
A30: 46171 | B30: VICTOR | C30: 62964
A31: 46109 | B31: WALTER | C31: 30800
A32: 46146 | B32: WALTER | C32: 40306

Sheet SEBA
A1: SEBA CTA CTE 30/05
A2: FECHA | B2: CLIENTE | C2: SALDO
A3: 46190 | B3: DIAZ ABRAHAM | C3: =7053513-1210000-700000 -> 5143513
A4: 46191 | B4: BEJAS DIEGO | C4: 425970
A5: 46191 | B5: GRAMAJO MARIA CONSTANZA | C5: =99026-20576 -> 78450
A6: 46191 | B6: BUSTOS SEBASTIAN | C6: 913867
A7: 46195 | B7: FIORENZA GUSTAVO | C7: 119262
A8: 46195 | B8: SORIA ROSALIA | C8: 274863
A9: 46196 | B9: EL JATIB | C9: =1493883-690261 -> 803622
A10: 46196 | B10: HARO TRINIDAD | C10: 107705
A11: 46197 | B11: ELIAS JORGE | C11: 634773
A12: 46197 | B12: ESPINOZA ALEXIS | C12: 493011
A13: 46197 | B13: ESTRADA VICTOR | C13: 1109771
A14: 46197 | B14: LAVAQUE NIEVES | C14: =221401-36750 -> 184651
A15: 46197 | B15: EL CEBILAR | C15: 542920
A16: 46197 | B16: HERRERA FERNANDO | C16: 113824
A17: 46197 | B17: ISLA VERDE | C17: 1980038
A18: 46197 | B18: NAVARRO ANDREA | C18: 119131
A19: 46197 | B19: PASTERIS LUIS | C19: 297715
A20: 46197 | B20: GIACOSA | C20: 198479
A21: 46199 | B21: BUSTOS CESAR | C21: 259092
A22: 46199 | B22: BUSTOS MARIA | C22: 254081
A23: 46199 | B23: DIAZ ROSA | C23: 266277
A24: 46202 | B24: AUAD MARIANA | C24: 999149
A25: 46202 | B25: BEJAS MATIAS | C25: 570681
A26: 46202 | B26: EL CEIBAL | C26: 164946
... A28: 46202 | B28: RAMIREZ MATIAS | C28: 454119
A29: 46203 | B29: GIMENEZ ROMINA | C29: =372022-50740 -> 321282
A30: 46203 | B30: BUSTOS JAVIER | C30: 919797
A31: 46203 | B31: GOMEZ OSVALDO | C31: =418617-6960 -> 411657
A32: 46203 | B32: IBAÑEZ NAHUEL | C32: 656770
A33: 46203 | B33: OTTONELLI LUCAS | C33: 675316
A34: 46203 | B34: REYES ROLDAN JULIETA | C34: 184682
A35: 46203 | B35: ROCHA SILVIA | C35: =205114-54021 -> 151093
A36: 46203 | B36: SIR VICTOR | C36: 2582312
A37: 46203 | B37: VIOJO ESTEBAN | C37: 1550791
C47: =SUM(C3:C45) -> 24454108

Sheet BRIAN
A1: BRIAN CTA CTE 30/05
A2: FECHA | B2: CLIENTE | C2: SALDO
B3: MORENO JOSE MARIA | C3: -17743
B4: VICENTE JOSE | C4: -5403
A5: 46185 | B5: DIP EZEQUIEL | C5: =279645-200000 -> 79645
A6: 46186 | B6: BAZAN DIEGO | C6: =367074-123000-100000 -> 144074
A7: 46186 | B7: CABRERA ROQUE | C7: =766440-201007 -> 565433
A8: 46190 | B8: AUTOSERVICIO ANDRADA | C8: =2030627-614073 -> 1416554
A9: 46190 | B9: SUPERHERRERA | C9: 786321
A10: 46192 | B10: AUTOSERVICIO NFAMILY | C10: 495363
A11: 46192 | B11: CEREALES Y LEGUMBRES | C11: 317522
A12: 46192 | B12: EL PICANTE | C12: 256631
A13: 46192 | B13: MONESTEROLO MERCEDES | C13: 347998
A14: 46197 | B14: CASTILLO PANCHO | C14: =698625-35000 -> 663625
A15: 46197 | B15: GOMEZ ANGEL | C15: =816187-700000 -> 116187
A16: 46197 | B16: HERRERA SILVIO | C16: 276327
A17: 46197 | B17: NUESTRO CAMPO | C17: =206415-31810 -> 174605
A18: 46197 | B18: SUPER EMANUEL | C18: 730483
A19: 46199 | B19: AUTOSERVICIO VYH | C19: 252674
A20: 46107 | B20: DANUN JUAN | C20: =162627-19158 -> 143469
A21: 46199 | B21: MINISERVICIO LAURA | C21: 779223
A22: 46199 | B22: SANCHEZ TELLO | C22: =191571-160000 -> 31571
A23: 46199 | B23: CABRERA ROQUE | C23: 399641
A24: 46199 | B24: DARWICH MARIELA | C24: 532638
A25: 46199 | B25: GIMENEZ CECILIA | C25: 532638
A26: 46199 | B26: HERNANDEZ EMILSE | C26: 96187
A27: 46199 | B27: MAYORISTA REYES | C27: 468178
A28: 46199 | B28: RADINO SUSANA | C28: 229388
A29: 46199 | B29: SUPER DEYUV | C29: 363667
A30: 46200 | B30: CARDENAS WALTER | C30: 610727
A31: 46200 | B31: CEREALES SAN VICENTE | C31: 409542
A32: 46200 | B32: JIMENEZ JOSE LEANDRO | C32: 161628
A33: 46200 | B33: DIP EZEQUIEL | C33: 7964
A34: 46200 | B34: BAZAN DIEGO | C34: 36707
C52: =SUM(C3:C46) -> 11403464

Sheet Hoja 15
A1: 73 | B1: 3 | C1: Veliz Marcelo
A2: 19 | B2: 3 | C2: Veliz Marcelo
A3: 333 | B3: 3 | C3: Veliz Marcelo
A4: 188 | B4: 3 | C4: Veliz Marcelo
A5: 65 | B5: 3 | C5: Veliz Marcelo
A6: 160 | B6: 3 | C6: Veliz Marcelo
A7: 780 | B7: 3 | C7: Veliz Marcelo
A8: 448 | B8: 3 | C8: Veliz Marcelo
A9: 109 | B9: 12 | C9: BRIAN
A10: 66 | B10: 3 | C10: Veliz Marcelo
A11: 442 | B11: 3 | C11: Veliz Marcelo
A12: 733 | B12: 3 | C12: Veliz Marcelo
... A258: 289 | B258: 4 | C258: Brandan Julio
A259: 822 | C259: Brandan Julio
A260: 492 | B260: 4 | C260: Brandan Julio
A261: 314 | B261: 4 | C261: Brandan Julio
A262: 283 | B262: 4 | C262: Brandan Julio
A263: 690 | B263: 4 | C263: Brandan Julio
A264: 240 | B264: 4 | C264: Brandan Julio
A265: 324 | B265: 4 | C265: Brandan Julio
A266: 443 | B266: 4 | C266: Brandan Julio
A267: 831 | B267: 4 | C267: Brandan Julio
A268: 171 | B268: 4 | C268: Brandan Julio
A269: 851 | B269: 4 | C269: Brandan Julio
A270: 50 | B270: 4 | C270: Brandan Julio
A271: 610 | B271: 4 | C271: Brandan Julio
... A529: 749 | B529: 12 | C529: BRIAN
A530: 832 | C530: BRIAN
A531: 619 | B531: 12 | C531: BRIAN
A532: 389 | B532: 12 | C532: BRIAN
A533: 903 | B533: 12 | C533: BRIAN
A534: 395 | B534: 3 | C534: Veliz Marcelo
A535: 292 | B535: 12 | C535: BRIAN
A536: 567 | B536: 12 | C536: BRIAN
A537: 944 | B537: 12 | C537: BRIAN
A538: 718 | B538: 12 | C538: BRIAN
A539: 549 | B539: 3 | C539: Veliz Marcelo
A540: 936 | B540: 12 | C540: BRIAN
A541: 715 | B541: 12 | C541: BRIAN
A542: 103 | B542: 12 | C542: BRIAN
...
