Workbook

Sheet ENERO
A1: FALTANTE DE MERCADERIA ENERO 2026
A2: FECHA | B2: CLIENTE | C2: VENDEDOR | D2: COD-ART | E2: ARTICULO | F2: MOTIVO | G2: CANTIDAD | H2: PRECIO | I2: TOTAL
A3: 46024 | B3: FORRAJERIA HUELLITAS | C3: JULIO | D3: 1016 | E3: =+VLOOKUP(D3,ARTICULO!$A$2:$B$1048576,2,FALSE) -> ARENA SANITARIA VITAL FUN X6K | F3: M.C DEPOSITO | G3: 3 | H3: 5558 | I3: =SUM(G3*H3) -> 16674
A4: 46055 | B4: FORRAJERIA HUELLITAS | C4: JULIO | D4: 507 | E4: =+VLOOKUP(D4,ARTICULO!$A$2:$B$1048576,2,FALSE) -> BICARBONATO | F4: DEVOLUCION | G4: 5 | H4: 3382 | I4: =SUM(G4*H4) -> 16910
A5: 46024 | B5: RENGEL FERNANDO | C5: BRIAN | D5: 704 | E5: =+VLOOKUP(D5,ARTICULO!$A$2:$B$1048576,2,FALSE) -> AVENA INSTANTANEA | F5: DEVOLUCION | G5: 10 | H5: 1737 | I5: =SUM(G5*H5) -> 17370
A6: 46024 | B6: SALAZAR MARIELA | C6: SEBASTIAN | D6: 103 | E6: =+VLOOKUP(D6,ARTICULO!$A$2:$B$1048576,2,FALSE) -> ROSCO COCK x 15 KG | F6: DEVOLUCION | G6: 5 | H6: 18448 | I6: =SUM(G6*H6) -> 92240
A7: 46024 | B7: SALAZAR MARIELA | C7: SEBASTIAN | D7: 200 | E7: =+VLOOKUP(D7,ARTICULO!$A$2:$B$1048576,2,FALSE) -> ROSCO GATO PESCADO x 10 KG | F7: DEVOLUCION | G7: 1 | H7: 18672 | I7: =SUM(G7*H7) -> 18672
A8: 46024 | B8: SALAZAR MARIELA | C8: SEBASTIAN | D8: 151 | E8: =+VLOOKUP(D8,ARTICULO!$A$2:$B$1048576,2,FALSE) -> ZIMPI X 25 KG | F8: DEVOLUCION | G8: 1 | H8: 21356 | I8: =SUM(G8*H8) -> 21356
A9: 46024 | B9: MEJIAS NESTOR | C9: MARCELO | D9: 470 | E9: =+VLOOKUP(D9,ARTICULO!$A$2:$B$1048576,2,FALSE) -> MEZCLA P/PAJARO | F9: M.C DEPOSITO | G9: 30 | H9: 1058 | I9: =SUM(G9*H9) -> 31740
A10: 46025 | B10: ARRIOLA ANA | C10: JULIO | D10: 362 | E10: =+VLOOKUP(D10,ARTICULO!$A$2:$B$1048576,2,FALSE) -> OSITOS DE MIEL x 2.5 Kg | F10: SIN DINERO | G10: 1 | H10: 12247 | I10: =SUM(G10*H10) -> 12247
A11: 46025 | B11: ARRIOLA ANA | C11: JULIO | D11: 352 | E11: =+VLOOKUP(D11,ARTICULO!$A$2:$B$1048576,2,FALSE) -> GRANOLA x 1.5 kg | F11: SIN DINERO | G11: 1 | H11: 11025 | I11: =SUM(G11*H11) -> 11025
A12: 46025 | B12: ARRIOLA ANA | C12: JULIO | D12: 610 | E12: =+VLOOKUP(D12,ARTICULO!$A$2:$B$1048576,2,FALSE) -> MIX ENERGETICO S/C | F12: SIN DINERO | G12: 3 | H12: 8828 | I12: =SUM(G12*H12) -> 26484
A13: 46025 | B13: ARRIOLA ANA | C13: JULIO | D13: 406 | E13: =+VLOOKUP(D13,ARTICULO!$A$2:$B$1048576,2,FALSE) -> MIX SEMILLAS | F13: SIN DINERO | G13: 1 | H13: 4135 | I13: =SUM(G13*H13) -> 4135
A14: 46025 | B14: ARRIOLA ANA | C14: JULIO | D14: 301 | E14: =+VLOOKUP(D14,ARTICULO!$A$2:$B$1048576,2,FALSE) -> ALMOHADITA DE FRUTILLA X 2.5 KG | F14: SIN DINERO | G14: 1 | H14: 17775 | I14: =SUM(G14*H14) -> 17775
... A97: 46039 | B97: BRUNO MAYRA | C97: JULIO | D97: 320 | E97: =+VLOOKUP(D97,ARTICULO!$A$2:$B$1048576,2,FALSE) -> BOLITAS DE CHOCOLATE x 2.5 Kg | F97: DEVOLUCION | G97: 1 | H97: 10421 | I97: =SUM(G97*H97) -> 10421
E98: =+VLOOKUP(D98,ARTICULO!$A$2:$B$1048576,2,FALSE) -> #N/A | I98: =SUM(G98*H98) -> 0
E99: =+VLOOKUP(D99,ARTICULO!$A$2:$B$1048576,2,FALSE) -> #N/A | I99: =SUM(G99*H99) -> 0
H100: TOTAL | I100: =SUM(I3:I97) -> 5899519
E219: RESUMEN
E220: M.C DEPOSITO | F220: =+SUMIF(F287:F333,E220,I119:I334) -> 0
E221: M.C VENDEDOR | F221: =+SUMIF(F287:F334,E221,I119:I334) -> 0
E222: FALTO | F222: =+SUMIF(F287:F334,E222,I119:I334) -> 0
E223: SIN DINERO | F223: =+SUMIF(F287:F334,E223,I119:I334) -> 0
E224: DEVOLUCION | F224: =+SUMIF(F287:F334,E224,I119:I334) -> 0
E225: CERRADO | F225: =+SUMIF(F287:F334,E225,I119:I334) -> 0
E226: ERROR SISTEMA | F226: =+SUMIF(F287:F334,E226,I119:I334) -> 0
E227: TOTAL | F227: =+SUM(F220:F226) -> 0
E230: RESUMEN POR VENDEDOR | F230: MARCELO
E231: M.C DEPOSITO | F231: =+SUMIFS($I$3:$I$218,$C$3:$C$218,$F$282,$F$3:$F$218,E231) -> 84099
E232: M.C VENDEDOR | F232: =+SUMIFS($I$3:$I$218,$C$3:$C$218,$F$282,$F$3:$F$218,E232) -> 0
E233: FALTO | F233: =+SUMIFS($I$3:$I$218,$C$3:$C$218,$F$282,$F$3:$F$218,E233) -> 43433
E234: SIN DINERO | F234: =+SUMIFS($I$3:$I$218,$C$3:$C$218,$F$282,$F$3:$F$218,E234) -> 0
E235: DEVOLUCION | F235: =+SUMIFS($I$3:$I$218,$C$3:$C$218,$F$282,$F$3:$F$218,E235) -> 2939751
E236: CERRADO | F236: =+SUMIFS($I$3:$I$218,$C$3:$C$218,$F$282,$F$3:$F$218,E236) -> 0
E237: TOTAL | F237: =+SUM(F231:F236) -> 3067283
E239: RESUMEN POR VENDEDOR | F239: JULIO
E240: M.C DEPOSITO | F240: =+SUMIFS($I$3:$I$218,$C$3:$C$218,$F$291,$F$3:$F$218,E240) -> 51882
E241: M.C VENDEDOR | F241: =+SUMIFS($I$3:$I$218,$C$3:$C$218,$F$291,$F$3:$F$218,E241) -> 0
E242: FALTO | F242: =+SUMIFS($I$3:$I$218,$C$3:$C$218,$F$291,$F$3:$F$218,E242) -> 38650
E243: SIN DINERO | F243: =+SUMIFS($I$3:$I$218,$C$3:$C$218,$F$291,$F$3:$F$218,E243) -> 146874
...

Sheet FEBRERO
A1: FALTANTE DE MERCADERIA FEBRERO 2026
A2: FECHA | B2: CLIENTE | C2: VENDEDOR | D2: COD-ART | E2: ARTICULO | F2: MOTIVO | G2: CANTIDAD | H2: PRECIO | I2: TOTAL
A3: 46056 | B3: FORRAJERIA SUPER LIMPIO | C3: BRIAN | D3: 463 | E3: =+VLOOKUP(D3,ARTICULO!$A$2:$B$1048576,2,FALSE) -> MAIZ QUEBRADO | F3: DEVOLUCION | G3: 1 | H3: 18685 | I3: =SUM(G3*H3) -> 18685
A4: 46056 | B4: FORRAJERIA SUPER LIMPIO | C4: BRIAN | D4: 652 | E4: =+VLOOKUP(D4,ARTICULO!$A$2:$B$1048576,2,FALSE) -> MANI SABORIZADO | F4: M.C. DEPOSITO | G4: 2 | H4: 4200 | I4: =SUM(G4*H4) -> 8400
A5: 46056 | B5: CORDOBA MARCELO | C5: JULIO | D5: 716 | E5: =+VLOOKUP(D5,ARTICULO!$A$2:$B$1048576,2,FALSE) -> HARINA P/TAMALES | F5: FALTO | G5: 25 | H5: 449 | I5: =SUM(G5*H5) -> 11225
A6: 46056 | B6: FALCO DIEGO | C6: SEBASTIAN | D6: 722 | E6: =+VLOOKUP(D6,ARTICULO!$A$2:$B$1048576,2,FALSE) -> POLENTA | F6: FALTO | G6: 25 | H6: 782 | I6: =SUM(G6*H6) -> 19550
A7: 46056 | B7: SARAVIA LAURA | C7: JULIO | D7: 722 | E7: =+VLOOKUP(D7,ARTICULO!$A$2:$B$1048576,2,FALSE) -> POLENTA | F7: FALTO | G7: 75 | H7: 782 | I7: =SUM(G7*H7) -> 58650
A8: 46056 | B8: ARON DAVID | C8: MARCELO | D8: 59 | E8: =+VLOOKUP(D8,ARTICULO!$A$2:$B$1048576,2,FALSE) -> INICIADOR X 40 KG | F8: DEVOLUCION | G8: 1 | H8: 32303 | I8: =SUM(G8*H8) -> 32303
A9: 46056 | B9: ARON DAVID | C9: MARCELO | D9: 704 | E9: =+VLOOKUP(D9,ARTICULO!$A$2:$B$1048576,2,FALSE) -> AVENA INSTANTANEA | F9: DEVOLUCION | G9: 10 | H9: 1557 | I9: =SUM(G9*H9) -> 15570
A10: 46056 | B10: ARON JORGE | C10: MARCELO | D10: 604 | E10: =+VLOOKUP(D10,ARTICULO!$A$2:$B$1048576,2,FALSE) -> CIRUELA PRESIDENTA | F10: DEVOLUCION | G10: 5 | H10: 9720 | I10: =SUM(G10*H10) -> 48600
A11: 46056 | B11: ESCOBAR YOHANA | C11: MARCELO | D11: 477 | E11: =+VLOOKUP(D11,ARTICULO!$A$2:$B$1048576,2,FALSE) -> MAIZ QUEBRADO MEDIANO X 30 KG | F11: M.C. DEPOSITO | G11: 1 | H11: 19528 | I11: =SUM(G11*H11) -> 19528
A12: 46025 | B12: ESCOBAR YOHANA | C12: MARCELO | D12: 478 | E12: =+VLOOKUP(D12,ARTICULO!$A$2:$B$1048576,2,FALSE) -> MAIZ QUEBRADO GRUESO X 30 KG | F12: M.C. DEPOSITO | G12: 1 | H12: 19528 | I12: =SUM(G12*H12) -> 19528
A13: 46057 | B13: CORREA GUSTAVO | C13: SEBASTIAN | D13: 212 | E13: =+VLOOKUP(D13,ARTICULO!$A$2:$B$1048576,2,FALSE) -> 9 LIVES GATITO x 8 KG | F13: DEVOLUCION | G13: 1 | H13: 28375 | I13: =SUM(G13*H13) -> 28375
A14: 46057 | B14: GONZALES MARIA CRISTINA | C14: JULIO | D14: 605 | E14: =+VLOOKUP(D14,ARTICULO!$A$2:$B$1048576,2,FALSE) -> CIRUELA SIN CAROZO | F14: M.C. DEPOSITO | G14: 2 | H14: 7800 | I14: =SUM(G14*H14) -> 15600
... A161: 46080 | B161: ALDERETE PATRICIA SUC II | C161: MARCELO | D161: 477 | E161: =+VLOOKUP(D161,ARTICULO!$A$2:$B$1048576,2,FALSE) -> MAIZ QUEBRADO MEDIANO X 30 KG | F161: M.C. DEPOSITO | G161: 3 | H161: 14689 | I161: =SUM(G161*H161) -> 44067
A162: 46080 | B162: GUERRA JAVIER | D162: 605 | E162: =+VLOOKUP(D162,ARTICULO!$A$2:$B$1048576,2,FALSE) -> CIRUELA SIN CAROZO | F162: DEVOLUCION | G162: 10 | H162: 7809 | I162: =SUM(G162*H162) -> 78090
A163: 46080 | B163: SOTO SERGIO | D163: 6 | E163: =+VLOOKUP(D163,ARTICULO!$A$2:$B$1048576,2,FALSE) -> CONEJO X 25 KG - CONECAR | F163: FALTO | G163: 1 | H163: 18264 | I163: =SUM(G163*H163) -> 18264
A164: 46080 | B164: SUPER ABASTO | C164: BRIAN | D164: 665 | E164: =+VLOOKUP(D164,ARTICULO!$A$2:$B$1048576,2,FALSE) -> PASTA DE MANI NATURAL X 1KG X6UD | F164: DEVOLUCION | G164: 1 | H164: 24539 | I164: =SUM(G164*H164) -> 24539
A165: 46080 | B165: BUSTOS CESAR | C165: SEBASTIAN | D165: 311 | E165: =+VLOOKUP(D165,ARTICULO!$A$2:$B$1048576,2,FALSE) -> ANILLOS FRUTADOS x 2.5 Kg | F165: FALTO | G165: 1 | H165: 12027 | I165: =SUM(G165*H165) -> 12027
A166: 46080 | B166: BUSTOS DENISSE | C166: SEBASTIAN | D166: 6 | E166: =+VLOOKUP(D166,ARTICULO!$A$2:$B$1048576,2,FALSE) -> CONEJO X 25 KG - CONECAR | F166: FALTO | G166: 1 | H166: 19226 | I166: =SUM(G166*H166) -> 19226
A167: 46080 | B167: GONZALES FACUNDO | C167: MARCELO | D167: 4 | E167: =+VLOOKUP(D167,ARTICULO!$A$2:$B$1048576,2,FALSE) -> POSTURA x 25 Kg | F167: DEVOLUCION | G167: 1 | H167: 18085 | I167: =SUM(G167*H167) -> 18085
A168: 46080 | B168: GUZMAN MATIAS | C168: SEBASTIAN | D168: 130 | E168: =+VLOOKUP(D168,ARTICULO!$A$2:$B$1048576,2,FALSE) -> GRAN CAMPEON AD ROJO Carne y Pollo X 21 KG | F168: FALTO | G168: 5 | H168: 25392 | I168: =SUM(G168*H168) -> 126960
A169: 46080 | B169: GUZMAN MATIAS | C169: SEBASTIAN | D169: 6 | E169: =+VLOOKUP(D169,ARTICULO!$A$2:$B$1048576,2,FALSE) -> CONEJO X 25 KG - CONECAR | F169: FALTO | G169: 1 | H169: 19226 | I169: =SUM(G169*H169) -> 19226
A170: 46080 | B170: LOBO IGNACIO | C170: MARCELO | D170: 10669 | E170: =+VLOOKUP(D170,ARTICULO!$A$2:$B$1048576,2,FALSE) -> MANI CON CASCARA KING X KG | F170: FALTO | G170: 5 | H170: 3516 | I170: =SUM(G170*H170) -> 17580
A171: 46080 | B171: LOBO IGNACIO | C171: MARCELO | D171: 716 | E171: =+VLOOKUP(D171,ARTICULO!$A$2:$B$1048576,2,FALSE) -> HARINA P/TAMALES | F171: DEVOLUCION | G171: 5 | H171: 777 | I171: =SUM(G171*H171) -> 3885
A172: 46081 | B172: JACOBO ALVARO | C172: MARCELO | D172: 491 | E172: =+VLOOKUP(D172,ARTICULO!$A$2:$B$1048576,2,FALSE) -> MEZCLA GALLO PREMIUM | F172: DEVOLUCION | G172: 300 | H172: 779 | I172: =SUM(G172*H172) -> 233700
A173: 46081 | B173: ARRIOLA MARIANA | C173: JULIO | D173: 470 | E173: =+VLOOKUP(D173,ARTICULO!$A$2:$B$1048576,2,FALSE) -> MEZCLA P/PAJARO | F173: SIN DINERO | G173: 5 | H173: 1372 | I173: =SUM(G173*H173) -> 6860
A174: 46081 | B174: ARRIOLA MARIANA | C174: JULIO | D174: 166 | E174: =+VLOOKUP(D174,ARTICULO!$A$2:$B$1048576,2,FALSE) -> FLECKY ADULTO CARNE X 21 KG | F174: SIN DINERO | G174: 1 | H174: 14392 | I174: =SUM(G174*H174) -> 14392
A175: 46081 | B175: ARRIOLA MARIANA | C175: JULIO | D175: 119 | E175: =+VLOOKUP(D175,ARTICULO!$A$2:$B$1048576,2,FALSE) -> TIERNITO GATITO X10KG | F175: SIN DINERO | G175: 1 | H175: 25814 | I175: =SUM(G175*H175) -> 25814
... A184: 46081 | B184: FIGUEREDO LIDIA | C184: JULIO | D184: 1213 | E184: =+VLOOKUP(D184,ARTICULO!$A$2:$B$1048576,2,FALSE) -> MACETA CLASICA N░ 13 | F184: DEVOLUCION | G184: 3 | H184: 434 | I184: =SUM(G184*H184) -> 1302
E185: =+VLOOKUP(D185,ARTICULO!$A$2:$B$1048576,2,FALSE) -> #N/A | I185: =SUM(G185*H185) -> 0
E186: =+VLOOKUP(D186,ARTICULO!$A$2:$B$1048576,2,FALSE) -> #N/A | I186: =SUM(G186*H186) -> 0
E187: =+VLOOKUP(D187,ARTICULO!$A$2:$B$1048576,2,FALSE) -> #N/A | I187: =SUM(G187*H187) -> 0
E188: =+VLOOKUP(D188,ARTICULO!$A$2:$B$1048576,2,FALSE) -> #N/A | I188: =SUM(G188*H188) -> 0
E189: =+VLOOKUP(D189,ARTICULO!$A$2:$B$1048576,2,FALSE) -> #N/A | I189: =SUM(G189*H189) -> 0
E190: =+VLOOKUP(D190,ARTICULO!$A$2:$B$1048576,2,FALSE) -> #N/A | I190: =SUM(G190*H190) -> 0
E191: =+VLOOKUP(D191,ARTICULO!$A$2:$B$1048576,2,FALSE) -> #N/A | I191: =SUM(G191*H191) -> 0
E192: =+VLOOKUP(D192,ARTICULO!$A$2:$B$1048576,2,FALSE) -> #N/A | I192: =SUM(G192*H192) -> 0
E193: =+VLOOKUP(D193,ARTICULO!$A$2:$B$1048576,2,FALSE) -> #N/A | I193: =SUM(G193*H193) -> 0
E194: =+VLOOKUP(D194,ARTICULO!$A$2:$B$1048576,2,FALSE) -> #N/A | I194: =SUM(G194*H194) -> 0
...

Sheet MARZO
A1: FALTANTE DE MERCADERIA MARZO 2026
A2: FECHA | B2: CLIENTE | C2: VENDEDOR | D2: COD-ART | E2: ARTICULO | F2: MOTIVO | G2: CANTIDAD | H2: PRECIO | I2: TOTAL
A3: 46083 | B3: MARTINEZ SANTIAGO | C3: SEBASTIAN | D3: 661 | E3: =+VLOOKUP(D3,ARTICULO!$A$2:$B$1048576,2,FALSE) -> PASTA DE MANI NATURAL X 485GR X 12U- Mani king | F3: CERRADO | G3: 3 | H3: 30396 | I3: =SUM(G3*H3) -> 91188
A4: 46083 | B4: SILMAN HECTOR | C4: JULIO | D4: 332 | E4: =+VLOOKUP(D4,ARTICULO!$A$2:$B$1048576,2,FALSE) -> CEREAL SIN AZUCAR X 2.5 KG | F4: DEVOLUCION | G4: 4 | H4: 9995 | I4: =SUM(G4*H4) -> 39980
A5: 46084 | B5: LEGUINA MAXIMILIANO | C5: JULIO | D5: 468 | E5: =+VLOOKUP(D5,ARTICULO!$A$2:$B$1048576,2,FALSE) -> MEZCLA GRUESA/MEDIANA | F5: CERRADO | G5: 5 | H5: 688 | I5: =SUM(G5*H5) -> 3440
A6: 46084 | B6: LEGUINA MAXIMILIANO | C6: JULIO | D6: 466 | E6: =+VLOOKUP(D6,ARTICULO!$A$2:$B$1048576,2,FALSE) -> MEZCLA CON VIT. (CANARIO) | F6: CERRADO | G6: 5 | H6: 1715 | I6: =SUM(G6*H6) -> 8575
A7: 46084 | B7: LEGUINA MAXIMILIANO | C7: JULIO | D7: 717 | E7: =+VLOOKUP(D7,ARTICULO!$A$2:$B$1048576,2,FALSE) -> LENTEJA | F7: CERRADO | G7: 5 | H7: 2985 | I7: =SUM(G7*H7) -> 14925
A8: 46084 | B8: LEGUINA MAXIMILIANO | C8: JULIO | D8: 1009 | E8: =+VLOOKUP(D8,ARTICULO!$A$2:$B$1048576,2,FALSE) -> PIEDRAS SANITARIAS X 20 KG | F8: CERRADO | G8: 10 | H8: 8046 | I8: =SUM(G8*H8) -> 80460
A9: 46084 | B9: LOPEZ DANIEL | C9: JULIO | D9: 7 | E9: =+VLOOKUP(D9,ARTICULO!$A$2:$B$1048576,2,FALSE) -> CONEJO X 25 KG - GEPSA | F9: DEVOLUCION | G9: 1 | H9: 17992 | I9: =SUM(G9*H9) -> 17992
A10: 46084 | B10: NUTRIMUNDO | C10: JULIO | D10: 704 | E10: =+VLOOKUP(D10,ARTICULO!$A$2:$B$1048576,2,FALSE) -> AVENA INSTANTANEA | F10: FALTO | G10: 5 | H10: 1797 | I10: =SUM(G10*H10) -> 8985
A11: 46085 | B11: LIZARRAGA PABLO | C11: SEBASTIAN | D11: 491 | E11: =+VLOOKUP(D11,ARTICULO!$A$2:$B$1048576,2,FALSE) -> MEZCLA GALLO PREMIUM | F11: DEVOLUCION | G11: 140 | H11: 779 | I11: =SUM(G11*H11) -> 109060
A12: 46085 | B12: SUPPA VICTORIO | C12: SEBASTIAN | D12: 524 | E12: =+VLOOKUP(D12,ARTICULO!$A$2:$B$1048576,2,FALSE) -> PIMENTON ESPAÐOL | F12: SIN DINERO | G12: 5 | H12: 3200 | I12: =SUM(G12*H12) -> 16000
A13: 46085 | B13: SUPPA VICTORIO | C13: SEBASTIAN | D13: 519 | E13: =+VLOOKUP(D13,ARTICULO!$A$2:$B$1048576,2,FALSE) -> PIMIENTA BLANCA | F13: SIN DINERO | G13: 5 | H13: 37500 | I13: =SUM(G13*H13) -> 187500
A14: 46085 | B14: SUPPA VICTORIO | C14: SEBASTIAN | D14: 514 | E14: =+VLOOKUP(D14,ARTICULO!$A$2:$B$1048576,2,FALSE) -> NUEZ MOSCADA | F14: SIN DINERO | G14: 10 | H14: 3944 | I14: =SUM(G14*H14) -> 39440
... A162: 46112 | B162: NUTRIMUNDO | C162: JULIO | D162: 607 | E162: =+VLOOKUP(D162,ARTICULO!$A$2:$B$1048576,2,FALSE) -> HIGOS | F162: DEVOLUCION | G162: 2 | H162: 10730 | I162: =SUM(G162*H162) -> 21460
E163: =+VLOOKUP(D163,ARTICULO!$A$2:$B$1048576,2,FALSE) -> #N/A | I163: =SUM(G163*H163) -> 0
E164: =+VLOOKUP(D164,ARTICULO!$A$2:$B$1048576,2,FALSE) -> #N/A | I164: =SUM(G164*H164) -> 0
E165: =+VLOOKUP(D165,ARTICULO!$A$2:$B$1048576,2,FALSE) -> #N/A | I165: =SUM(G165*H165) -> 0
H166: TOTAL | I166: =SUM(I3:I165) -> 5249445.9
E167: RESUMEN
E168: M.C. DEPOSITO | F168: =+SUMIF(F3:F165,E168,I3:I165) -> 225552
E169: M.C. VENDEDOR | F169: =+SUMIF(F3:F165,E169,I3:I165) -> 242819
E170: FALTO | F170: =+SUMIF(F3:F165,E170,I3:I165) -> 96381
E171: SIN DINERO | F171: =+SUMIF(F3:F165,E171,I3:I165) -> 1083233
E172: DEVOLUCION | F172: =+SUMIF(F3:F165,E172,I3:I165) -> 2254330.9
E173: CERRADO | F173: =+SUMIF(F3:F165,E173,I3:I165) -> 1347130
E174: ERROR SISTEMA | F174: =+SUMIF(F3:F165,E174,I3:I165) -> 0
E175: TOTAL | F175: =+SUM(F168:F174) -> 5249445.9
E178: RESUMEN POR VENDEDOR | F178: MARCELO
E179: M.C. DEPOSITO | F179: =+SUMIFS($I$3:$I$165,$C$3:$C$165,$F$178,$F$3:$F$165,E179) -> 176371
E180: M.C. VENDEDOR | F180: =+SUMIFS($I$3:$I$165,$C$3:$C$165,$F$178,$F$3:$F$165,E180) -> 242819
E181: FALTO | F181: =+SUMIFS($I$3:$I$165,$C$3:$C$165,$F$178,$F$3:$F$165,E181) -> 0
E182: SIN DINERO | F182: =+SUMIFS($I$3:$I$165,$C$3:$C$165,$F$178,$F$3:$F$165,E182) -> 0
E183: DEVOLUCION | F183: =+SUMIFS($I$3:$I$165,$C$3:$C$165,$F$178,$F$3:$F$165,E183) -> 684480
E184: CERRADO | F184: =+SUMIFS($I$3:$I$165,$C$3:$C$165,$F$178,$F$3:$F$165,E184) -> 940476
E185: TOTAL | F185: =+SUM(F179:F184) -> 2044146
E187: RESUMEN POR VENDEDOR | F187: JULIO
E188: M.C. DEPOSITO | F188: =+SUMIFS($I$3:$I$165,$C$3:$C$165,$F$187,$F$3:$F$165,E188) -> 23516
E189: M.C. VENDEDOR | F189: =+SUMIFS($I$3:$I$165,$C$3:$C$165,$F$187,$F$3:$F$165,E189) -> 0
E190: FALTO | F190: =+SUMIFS($I$3:$I$165,$C$3:$C$165,$F$187,$F$3:$F$165,E190) -> 96381
...

Sheet ABRIL
A1: FALTANTE DE MERCADERIA ABRIL 2026
A2: FECHA | B2: CLIENTE | C2: VENDEDOR | D2: COD-ART | E2: ARTICULO | F2: MOTIVO | G2: CANTIDAD | H2: PRECIO | I2: TOTAL
A3: 46113 | B3: HERNANDEZ EMILSE | C3: MARCELO | D3: 723 | E3: =+VLOOKUP(D3,ARTICULO!$A$2:$B$1048576,2,FALSE) -> POROTO ALUBIA | F3: DEVOLUCION | G3: 5 | H3: 3840 | I3: =SUM(G3*H3) -> 19200
A4: 46113 | B4: ARRIETA YAQUELIN | C4: MARCELO | D4: 724 | E4: =+VLOOKUP(D4,ARTICULO!$A$2:$B$1048576,2,FALSE) -> POROTO PALLARES | F4: DEVOLUCION | G4: 25 | H4: 5265 | I4: =SUM(G4*H4) -> 131625
A5: 46113 | B5: DAVILA ANGEL | C5: BRIAN | D5: 685 | E5: =+VLOOKUP(D5,ARTICULO!$A$2:$B$1048576,2,FALSE) -> PASTA MANI NATURAL 4KG x 2U-Mani king | F5: DEVOLUCION | G5: 1 | H5: 32909 | I5: =SUM(G5*H5) -> 32909
A6: 46113 | B6: ARRIETA ARIEL | C6: MARCELO | D6: 1957 | E6: =+VLOOKUP(D6,ARTICULO!$A$2:$B$1048576,2,FALSE) -> BRUMOLINE CEBO X 50 GR | F6: DEVOLUCION | G6: 48 | H6: 1652 | I6: =SUM(G6*H6) -> 79296
A7: 46113 | B7: ALBORNOZ PALMIRA | C7: MARCELO | D7: 719 | E7: =+VLOOKUP(D7,ARTICULO!$A$2:$B$1048576,2,FALSE) -> MAIZ MOLIDO AMARILLO | F7: CERRADO | G7: 30 | H7: 931 | I7: =SUM(G7*H7) -> 27930
A8: 46113 | B8: ALBORNOZ PALMIRA | C8: MARCELO | D8: 721 | E8: =+VLOOKUP(D8,ARTICULO!$A$2:$B$1048576,2,FALSE) -> PISINGALLO | F8: CERRADO | G8: 25 | H8: 783 | I8: =SUM(G8*H8) -> 19575
A9: 46113 | B9: ALBORNOZ PALMIRA | C9: MARCELO | D9: 703 | E9: =+VLOOKUP(D9,ARTICULO!$A$2:$B$1048576,2,FALSE) -> AVENA ARROLLADA | F9: CERRADO | G9: 10 | H9: 1505 | I9: =SUM(G9*H9) -> 15050
A10: 46113 | B10: APARICIO EDUARDO | C10: JULIO | D10: 311 | E10: =+VLOOKUP(D10,ARTICULO!$A$2:$B$1048576,2,FALSE) -> ANILLOS FRUTADOS x 2.5 Kg | F10: M.C. DEPOSITO | G10: 1 | H10: 14450 | I10: =SUM(G10*H10) -> 14450
A11: 46116 | B11: DIAZ ARIEL | C11: MARCELO | D11: 722 | E11: =+VLOOKUP(D11,ARTICULO!$A$2:$B$1048576,2,FALSE) -> POLENTA | F11: DEVOLUCION | G11: 50 | H11: 739 | I11: =SUM(G11*H11) -> 36950
A12: 46116 | B12: EL CEIBAL | C12: SEBASTIAN | D12: 311 | E12: =+VLOOKUP(D12,ARTICULO!$A$2:$B$1048576,2,FALSE) -> ANILLOS FRUTADOS x 2.5 Kg | F12: SIN STOCK | G12: 1 | H12: 12027 | I12: =SUM(G12*H12) -> 12027
A13: 46116 | B13: EL CEIBAL | C13: SEBASTIAN | D13: 352 | E13: =+VLOOKUP(D13,ARTICULO!$A$2:$B$1048576,2,FALSE) -> GRANOLA x 1.5 kg | F13: M.C. DEPOSITO | G13: 1 | H13: 11192 | I13: =SUM(G13*H13) -> 11192
A14: 46119 | B14: GABRIEL ANGEL | C14: JULIO | D14: 717 | E14: =+VLOOKUP(D14,ARTICULO!$A$2:$B$1048576,2,FALSE) -> LENTEJA | F14: DEVOLUCION | G14: 10 | H14: 2245 | I14: =SUM(G14*H14) -> 22450
... A146: 46142 | B146: SORAIDE JOSE MARIA | C146: MARCELO | D146: 903 | E146: =+VLOOKUP(D146,ARTICULO!$A$2:$B$1048576,2,FALSE) -> BANDEJA SANITARIA | F146: CERRADO | G146: 6 | H146: 2320 | I146: =SUM(G146*H146) -> 13920
A147: 46142 | B147: FORRAJERIA LANZY | C147: BRIAN | D147: 457 | E147: =+VLOOKUP(D147,ARTICULO!$A$2:$B$1048576,2,FALSE) -> GIRASOL CHICO | F147: CERRADO | G147: 30 | H147: 1246 | I147: =SUM(H147*G147) -> 37380
E148: =+VLOOKUP(D148,ARTICULO!$A$2:$B$1048576,2,FALSE) -> #N/A
E149: =+VLOOKUP(D149,ARTICULO!$A$2:$B$1048576,2,FALSE) -> #N/A
E150: =+VLOOKUP(D150,ARTICULO!$A$2:$B$1048576,2,FALSE) -> #N/A
E151: =+VLOOKUP(D151,ARTICULO!$A$2:$B$1048576,2,FALSE) -> #N/A
E152: =+VLOOKUP(D152,ARTICULO!$A$2:$B$1048576,2,FALSE) -> #N/A
E153: =+VLOOKUP(D153,ARTICULO!$A$2:$B$1048576,2,FALSE) -> #N/A
E154: =+VLOOKUP(D154,ARTICULO!$A$2:$B$1048576,2,FALSE) -> #N/A
E155: =+VLOOKUP(D155,ARTICULO!$A$2:$B$1048576,2,FALSE) -> #N/A
E156: =+VLOOKUP(D156,ARTICULO!$A$2:$B$1048576,2,FALSE) -> #N/A
E157: =+VLOOKUP(D157,ARTICULO!$A$2:$B$1048576,2,FALSE) -> #N/A
E158: =+VLOOKUP(D158,ARTICULO!$A$2:$B$1048576,2,FALSE) -> #N/A
E159: =+VLOOKUP(D159,ARTICULO!$A$2:$B$1048576,2,FALSE) -> #N/A
... E169: =+VLOOKUP(D169,ARTICULO!$A$2:$B$1048576,2,FALSE) -> #N/A
H170: TOTAL | I170: =SUM(I3:I169) -> 5028681
E171: RESUMEN
E172: M.C. DEPOSITO | F172: =+SUMIF(F3:F169,E172,I3:I169) -> 183391
E173: M.C VENDEDOR | F173: =+SUMIF(F3:F169,E173,I3:I169) -> 633220
E174: SIN STOCK | F174: =+SUMIF(F3:F169,E174,I3:I169) -> 427224
E175: SIN DINERO | F175: =+SUMIF(F3:F169,E175,I3:I169) -> 636070
E176: DEVOLUCION | F176: =+SUMIF(F3:F169,E176,I3:I169) -> 2640312
E177: CERRADO | F177: =+SUMIF(F3:F169,E177,I3:I169) -> 508464
E178: ERROR SISTEMA | F178: =+SUMIF(F3:F169,E178,I3:I169) -> 0
E179: TOTAL | F179: =+SUM(F172:F178) -> 5028681
E182: RESUMEN POR VENDEDOR | F182: MARCELO
...

Sheet MAYO
A1: FALTANTE DE MERCADERIA MAYO 2026
A2: FECHA | B2: CLIENTE | C2: VENDEDOR | D2: COD-ART | E2: ARTICULO | F2: MOTIVO | G2: CANTIDAD | H2: PRECIO | I2: TOTAL
A3: 46144 | B3: ARRIOLA MARIANA | C3: JULIO | D3: 130 | E3: =+VLOOKUP(D3,ARTICULO!$A$2:$B$1048576,2,FALSE) -> GRAN CAMPEON AD ROJO Carne y Pollo X 21 KG | F3: CERRADO | G3: 1 | H3: 25392 | I3: =SUM(G3*H3) -> 25392
A4: 46144 | B4: ARRIOLA MARIANA | C4: JULIO | D4: 131 | E4: =+VLOOKUP(D4,ARTICULO!$A$2:$B$1048576,2,FALSE) -> GRAN CAMPEON CACHORRO X 10 KG | F4: CERRADO | G4: 1 | H4: 15514 | I4: =SUM(G4*H4) -> 15514
A5: 46144 | B5: ARRIOLA MARIANA | C5: JULIO | D5: 610 | E5: =+VLOOKUP(D5,ARTICULO!$A$2:$B$1048576,2,FALSE) -> MIX ENERGETICO S/C | F5: CERRADO | G5: 1 | H5: 8103 | I5: =SUM(G5*H5) -> 8103
A6: 46144 | B6: ARRIOLA MARIANA | C6: JULIO | D6: 482 | E6: =+VLOOKUP(D6,ARTICULO!$A$2:$B$1048576,2,FALSE) -> MEZCLA FINA ESPECIAL (CARDENAL) | F6: CERRADO | G6: 5 | H6: 846 | I6: =SUM(G6*H6) -> 4230
A7: 46144 | B7: ARRIOLA MARIANA | C7: JULIO | D7: 508 | E7: =+VLOOKUP(D7,ARTICULO!$A$2:$B$1048576,2,FALSE) -> COCO RALLADO | F7: CERRADO | G7: 1 | H7: 10050 | I7: =SUM(G7*H7) -> 10050
A8: 46144 | B8: ARRIOLA MARIANA | C8: JULIO | D8: 470 | E8: =+VLOOKUP(D8,ARTICULO!$A$2:$B$1048576,2,FALSE) -> MEZCLA P/PAJARO | F8: CERRADO | G8: 5 | H8: 1350 | I8: =SUM(G8*H8) -> 6750
A9: 46144 | B9: ARRIOLA MARIANA | C9: JULIO | D9: 320 | E9: =+VLOOKUP(D9,ARTICULO!$A$2:$B$1048576,2,FALSE) -> BOLITAS DE CHOCOLATE x 2.5 Kg | F9: CERRADO | G9: 1 | H9: 15327 | I9: =SUM(G9*H9) -> 15327
A10: 46144 | B10: ARRIOLA MARIANA | C10: JULIO | D10: 612 | E10: =+VLOOKUP(D10,ARTICULO!$A$2:$B$1048576,2,FALSE) -> NUEZ PELADA AMBAR | F10: CERRADO | G10: 1 | H10: 17550 | I10: =SUM(G10*H10) -> 17550
A11: 46144 | B11: FIGUEREDO LIDIA | C11: JULIO | D11: 352 | E11: =+VLOOKUP(D11,ARTICULO!$A$2:$B$1048576,2,FALSE) -> GRANOLA x 1.5 kg | F11: M.C. DEPOSITO | G11: 10 | H11: 10345 | I11: =SUM(G11*H11) -> 103450 | J11: ELVIO
A12: 46144 | B12: FORRAJERIA CHOC | C12: JULIO | D12: 166 | E12: =+VLOOKUP(D12,ARTICULO!$A$2:$B$1048576,2,FALSE) -> FLECKY ADULTO CARNE X 21 KG | F12: SIN STOCK | G12: 2 | H12: 14392 | I12: =SUM(G12*H12) -> 28784
A13: 46144 | B13: MARTIN FACUNDO | C13: JULIO | D13: 173 | E13: =+VLOOKUP(D13,ARTICULO!$A$2:$B$1048576,2,FALSE) -> BALANCED CACHORRO RAZA MED X 20KG | F13: SIN STOCK | G13: 1 | H13: 85979 | I13: =SUM(G13*H13) -> 85979
A14: 46144 | B14: BUSTOS LUIS | C14: MARCELO | D14: 1968 | E14: =+VLOOKUP(D14,ARTICULO!$A$2:$B$1048576,2,FALSE) -> ULTRA RATICIDA 30 SOBRES X 50 GR | F14: DEVOLUCION | G14: 30 | H14: 1161 | I14: =SUM(G14*H14) -> 34830
A15: 46146 | B15: BRANDAN FEDERICO | C15: MARCELO | D15: 405 | E15: =+VLOOKUP(D15,ARTICULO!$A$2:$B$1048576,2,FALSE) -> SESAMO | F15: DEVOLUCION | G15: 10 | H15: 2186 | I15: =SUM(G15*H15) -> 21860
A16: 46147 | B16: ROCHA SILVIA | C16: SEBASTIAN | D16: 134 | E16: =+VLOOKUP(D16,ARTICULO!$A$2:$B$1048576,2,FALSE) -> BELCAN ADULTOS X 22KG | F16: SIN DINERO | G16: 2 | H16: 27403 | I16: =SUM(G16*H16) -> 54806
A17: 46117 | B17: ROCHA SILVIA | C17: SEBASTIAN | D17: 602 | E17: =+VLOOKUP(D17,ARTICULO!$A$2:$B$1048576,2,FALSE) -> CIRUELA | F17: SIN DINERO | G17: 3 | H17: 6412 | I17: =SUM(G17*H17) -> 19236
A18: 46117 | B18: IBAÑEZ NAHUEL | C18: SEBASTIAN | D18: 57 | E18: =+VLOOKUP(D18,ARTICULO!$A$2:$B$1048576,2,FALSE) -> PONEDORA POSTURA X 40 KG | F18: DEVOLUCION | G18: 1 | H18: 20427 | I18: =SUM(G18*H18) -> 20427
A19: 46148 | B19: SORIA ALBERO | C19: BRIAN | D19: 117 | E19: =+VLOOKUP(D19,ARTICULO!$A$2:$B$1048576,2,FALSE) -> TIERNITO CACHO x 21 KG | F19: SIN DINERO | G19: 1 | H19: 38045 | I19: =SUM(G19*H19) -> 38045
A20: 46148 | B20: SORIA ALBERO | C20: BRIAN | D20: 150 | E20: =+VLOOKUP(D20,ARTICULO!$A$2:$B$1048576,2,FALSE) -> ZIMPI X 15 KG | F20: SIN DINERO | G20: 2 | H20: 13962 | I20: =SUM(G20*H20) -> 27924
A21: 46148 | B21: SORIA ALBERO | C21: BRIAN | D21: 185 | E21: =+VLOOKUP(D21,ARTICULO!$A$2:$B$1048576,2,FALSE) -> ZIMPI GATO X 15 KG | F21: SIN DINERO | G21: 3 | H21: 22790 | I21: =SUM(G21*H21) -> 68370
A22: 46148 | B22: PAZ VANESA | C22: JULIO | D22: 10 | E22: =+VLOOKUP(D22,ARTICULO!$A$2:$B$1048576,2,FALSE) -> PAJARO 4 mm x 25 Kg - GANAVE | F22: DEVOLUCION | G22: 1 | H22: 47418 | I22: =SUM(G22*H22) -> 47418
A23: 46149 | B23: ANDRADES | C23: MARCELO | D23: 151 | E23: =+VLOOKUP(D23,ARTICULO!$A$2:$B$1048576,2,FALSE) -> ZIMPI X 25 KG | F23: M.C. DEPOSITO | G23: 30 | H23: 17090 | I23: =SUM(G23*H23) -> 512700 | J23: SUSANA
A24: 46149 | B24: DIAZ ALFREDO | C24: MARCELO | D24: 468 | E24: =+VLOOKUP(D24,ARTICULO!$A$2:$B$1048576,2,FALSE) -> MEZCLA GRUESA/MEDIANA | F24: DEVOLUCION | G24: 120 | H24: 530 | I24: =SUM(G24*H24) -> 63600
A25: 46149 | B25: FERNANDEZ DANIEL | C25: JULIO | D25: 652 | E25: =+VLOOKUP(D25,ARTICULO!$A$2:$B$1048576,2,FALSE) -> MANI SABORIZADO | F25: SIN STOCK | G25: 1 | H25: 4200 | I25: =SUM(G25*H25) -> 4200
A26: 46149 | B26: NARCHER PAMELA | C26: MARCELO | D26: 117 | E26: =+VLOOKUP(D26,ARTICULO!$A$2:$B$1048576,2,FALSE) -> TIERNITO CACHO x 21 KG | F26: DEVOLUCION | G26: 2 | H26: 36043 | I26: =SUM(G26*H26) -> 72086
A27: 46149 | B27: NARCHER PAMELA | C27: MARCELO | D27: 6 | E27: =+VLOOKUP(D27,ARTICULO!$A$2:$B$1048576,2,FALSE) -> CONEJO X 25 KG - CONECAR | F27: SIN STOCK | G27: 1 | H27: 17777 | I27: =SUM(G27*H27) -> 17777
A28: 46149 | B28: GRAMAJO MARIA CONSTANZA | C28: SEBASTIAN | D28: 330 | E28: =+VLOOKUP(D28,ARTICULO!$A$2:$B$1048576,2,FALSE) -> CEREAL CON AZUCAR x 2.5 Kg | F28: DEVOLUCION | G28: 4 | H28: 11633 | I28: =SUM(G28*H28) -> 46532
A29: 46149 | B29: GRAMAJO MARIA CONSTANZA | C29: SEBASTIAN | D29: 410 | E29: =+VLOOKUP(D29,ARTICULO!$A$2:$B$1048576,2,FALSE) -> SALVADO DE TRIGO | F29: SIN STOCK | G29: 10 | H29: 980 | I29: =SUM(G29*H29) -> 9800
A30: 46146 | B30: MANTARAS MARIANO | C30: JULIO | D30: 169 | E30: =+VLOOKUP(D30,ARTICULO!$A$2:$B$1048576,2,FALSE) -> COMPLETE PERRO ADULTO RAZA MED Y GDE X 20KG | F30: M.C. DEPOSITO | G30: 1 | H30: 52776 | I30: =SUM(G30*H30) -> 52776 | J30: ELVIO
A31: 46149 | B31: ARRIETA YAQUELIN | C31: MARCELO | D31: 1905 | E31: =+VLOOKUP(D31,ARTICULO!$A$2:$B$1048576,2,FALSE) -> FERTIFOX HORM. ENRAIZAR x 75 gr | F31: DEVOLUCION | G31: 3 | H31: 6969 | I31: =SUM(G31*H31) -> 20907
A32: 46149 | B32: IBRAHIM ZULEMA | C32: MARCELO | D32: 6 | E32: =+VLOOKUP(D32,ARTICULO!$A$2:$B$1048576,2,FALSE) -> CONEJO X 25 KG - CONECAR | F32: SIN STOCK | G32: 1 | H32: 15685 | I32: =SUM(G32*H32) -> 15685
A33: 46241 | B33: VAQUERA FEDERICO | C33: BRIAN | D33: 491 | E33: =+VLOOKUP(D33,ARTICULO!$A$2:$B$1048576,2,FALSE) -> MEZCLA GALLO PREMIUM | F33: M.C. VENDEDOR | G33: 150 | H33: 801 | I33: =SUM(G33*H33) -> 120150
A34: 46150 | B34: BUSTOS MARIA | C34: SEBASTIAN | D34: 652 | E34: =+VLOOKUP(D34,ARTICULO!$A$2:$B$1048576,2,FALSE) -> MANI SABORIZADO | F34: SIN STOCK | G34: 2 | H34: 4200 | I34: =SUM(G34*H34) -> 8400
A35: 46150 | B35: GONZALEZ FACUNDO | C35: MARCELO | D35: 6 | E35: =+VLOOKUP(D35,ARTICULO!$A$2:$B$1048576,2,FALSE) -> CONEJO X 25 KG - CONECAR | F35: SIN STOCK | G35: 1 | H35: 17777 | I35: =SUM(G35*H35) -> 17777
A36: 46150 | B36: BUSTOS MARIA | C36: SEBASTIAN | D36: 652 | E36: =+VLOOKUP(D36,ARTICULO!$A$2:$B$1048576,2,FALSE) -> MANI SABORIZADO | F36: SIN STOCK | G36: 2 | H36: 4200 | I36: =SUM(G36*H36) -> 8400
A37: 46150 | B37: IBAÑEZ NANCY | C37: MARCELO | D37: 1950 | E37: =+VLOOKUP(D37,ARTICULO!$A$2:$B$1048576,2,FALSE) -> GERMANI GEL JERINGA X 5 GR | F37: M.C. DEPOSITO | G37: 6 | H37: 3284 | I37: =SUM(G37*H37) -> 19704 | J37: ELVIO
A38: 46150 | B38: LOBO IGNACIO | C38: MARCELO | D38: 6 | E38: =+VLOOKUP(D38,ARTICULO!$A$2:$B$1048576,2,FALSE) -> CONEJO X 25 KG - CONECAR | F38: SIN STOCK | G38: 2 | H38: 17777 | I38: =SUM(G38*H38) -> 35554
A39: 46150 | B39: NAVARRO ROSA | C39: SEBASTIAN | D39: 10672 | E39: =+VLOOKUP(D39,ARTICULO!$A$2:$B$1048576,2,FALSE) -> MANI TOSTADO SALADO X KG - Mani king | F39: DEVOLUCION | G39: 1 | H39: 4810 | I39: =SUM(G39*H39) -> 4810
A40: 46150 | B40: HERNANDEZ EMILSE | C40: BRIAN | D40: 1950 | E40: =+VLOOKUP(D40,ARTICULO!$A$2:$B$1048576,2,FALSE) -> GERMANI GEL JERINGA X 5 GR | F40: DEVOLUCION | G40: 2 | H40: 20020 | I40: =SUM(G40*H40) -> 40040
...

Sheet JUNIO
A1: FALTANTE DE MERCADERIA JUNIO 2026
A2: FECHA | B2: CLIENTE | C2: VENDEDOR | D2: COD-ART | E2: ARTICULO | F2: MOTIVO | G2: CANTIDAD | H2: PRECIO | I2: TOTAL
A3: 46174 | B3: ESCOBAR YOHANA | C3: MARCELO | D3: 1009 | E3: =+VLOOKUP(D3,ARTICULO!$A$2:$B$1048576,2,FALSE) -> PIEDRAS SANITARIAS X 20 KG | F3: DEVOLUCION | G3: 15 | H3: 9256 | I3: =SUM(G3*H3) -> 138840
A4: 46174 | B4: ESCOBAR YOHANA | C4: MARCELO | D4: 957 | E4: =+VLOOKUP(D4,ARTICULO!$A$2:$B$1048576,2,FALSE) -> OREJAS | F4: DEVOLUCION | G4: 10 | H4: 778 | I4: =SUM(G4*H4) -> 7780
A5: 46174 | B5: LUNA DIANA | C5: MARCELO | D5: 310 | E5: =+VLOOKUP(D5,ARTICULO!$A$2:$B$1048576,2,FALSE) -> ANILLOS DE MIEL X 2.5 KG | F5: DEVOLUCION | G5: 1 | H5: 12899 | I5: =SUM(G5*H5) -> 12899
A6: 46174 | B6: LUNA DIANA | C6: MARCELO | D6: 478 | E6: =+VLOOKUP(D6,ARTICULO!$A$2:$B$1048576,2,FALSE) -> MAIZ QUEBRADO GRUESO X 30 KG | F6: DEVOLUCION | G6: 1 | H6: 14289 | I6: =SUM(G6*H6) -> 14289
A7: 46174 | B7: ARON JORGE | C7: MARCELO | D7: 700 | E7: =+VLOOKUP(D7,ARTICULO!$A$2:$B$1048576,2,FALSE) -> ARROZ | F7: DEVOLUCION | G7: 50 | H7: 1487 | I7: =SUM(G7*H7) -> 74350
A8: 46175 | B8: BUSTOS GRACIELA | C8: JULIO | D8: 131 | E8: =+VLOOKUP(D8,ARTICULO!$A$2:$B$1048576,2,FALSE) -> GRAN CAMPEON CACHORRO X 10 KG | F8: DEVOLUCION | G8: 1 | H8: 16755 | I8: =SUM(G8*H8) -> 16755
A9: 46175 | B9: ESPECHE CARLOS | C9: SEBASTIAN | D9: 958 | E9: =+VLOOKUP(D9,ARTICULO!$A$2:$B$1048576,2,FALSE) -> PALITA SANITARIA | F9: DEVOLUCION | G9: 2 | H9: 588 | I9: =SUM(G9*H9) -> 1176
A10: 46176 | B10: ANTA MARGARITA | C10: JULIO | D10: 970 | E10: =+VLOOKUP(D10,ARTICULO!$A$2:$B$1048576,2,FALSE) -> POLAR N░ 3 | F10: DEVOLUCION | G10: 1 | H10: 2553 | I10: =SUM(G10*H10) -> 2553
A11: 46176 | B11: ALBORNOZ PALMIRA | C11: MARCELO | D11: 521 | E11: =+VLOOKUP(D11,ARTICULO!$A$2:$B$1048576,2,FALSE) -> PROVENZAL | F11: DEVOLUCION | G11: 3 | H11: 2935 | I11: =SUM(G11*H11) -> 8805
A12: 46176 | B12: ALBORNOZ PALMIRA | C12: MARCELO | D12: 515 | E12: =+VLOOKUP(D12,ARTICULO!$A$2:$B$1048576,2,FALSE) -> OREGANO | F12: DEVOLUCION | G12: 5 | H12: 3975 | I12: =SUM(G12*H12) -> 19875
A13: 46177 | B13: ANDOAIN AMALIA | C13: SEBASTIAN | D13: 301 | E13: =+VLOOKUP(D13,ARTICULO!$A$2:$B$1048576,2,FALSE) -> ALMOHADITA DE FRUTILLA X 2.5 KG | F13: M.C. VENDEDOR | G13: 3 | H13: 17705 | I13: =SUM(G13*H13) -> 53115
A14: 46177 | B14: ANDOAIN AMALIA | C14: SEBASTIAN | D14: 302 | E14: =+VLOOKUP(D14,ARTICULO!$A$2:$B$1048576,2,FALSE) -> ALMOHADITA DE LIMON X 2.5 KG | F14: M.C. VENDEDOR | G14: 2 | H14: 17199 | I14: =SUM(G14*H14) -> 34398
... A164: 46200 | B164: MARTIN FACUNDO | C164: JULIO | D164: 719 | E164: =+VLOOKUP(D164,ARTICULO!$A$2:$B$1048576,2,FALSE) -> MAIZ MOLIDO AMARILLO | F164: M.C. VENDEDOR | G164: 5 | H164: 1073 | I164: =SUM(G164*H164) -> 5365
A165: 46203 | B165: GIMENEZ ROMINA | C165: SEBASTIAN | D165: 235 | E165: EXACT CRIADORES CACHORRO X15 | F165: DEVOLUCION | G165: 3 | H165: $ 16,913.00 | I165: $ 50,739.00
E166: =+VLOOKUP(D166,ARTICULO!$A$2:$B$1048576,2,FALSE) -> #N/A
E167: =+VLOOKUP(D167,ARTICULO!$A$2:$B$1048576,2,FALSE) -> #N/A
E168: =+VLOOKUP(D168,ARTICULO!$A$2:$B$1048576,2,FALSE) -> #N/A
E169: =+VLOOKUP(D169,ARTICULO!$A$2:$B$1048576,2,FALSE) -> #N/A
E170: =+VLOOKUP(D170,ARTICULO!$A$2:$B$1048576,2,FALSE) -> #N/A
E171: =+VLOOKUP(D171,ARTICULO!$A$2:$B$1048576,2,FALSE) -> #N/A
E172: =+VLOOKUP(D172,ARTICULO!$A$2:$B$1048576,2,FALSE) -> #N/A
E173: =+VLOOKUP(D173,ARTICULO!$A$2:$B$1048576,2,FALSE) -> #N/A
E174: =+VLOOKUP(D174,ARTICULO!$A$2:$B$1048576,2,FALSE) -> #N/A
E175: =+VLOOKUP(D175,ARTICULO!$A$2:$B$1048576,2,FALSE) -> #N/A
E176: =+VLOOKUP(D176,ARTICULO!$A$2:$B$1048576,2,FALSE) -> #N/A
E177: =+VLOOKUP(D177,ARTICULO!$A$2:$B$1048576,2,FALSE) -> #N/A
... E270: =+VLOOKUP(D270,ARTICULO!$A$2:$B$1048576,2,FALSE) -> #N/A
H271: TOTAL | I271: =SUM(I3:I270) -> 6837919
E272: RESUMEN
E273: M.C. DEPOSITO S. | F273: $ 241,086.00
E274: M.C. DEPOSITO E. | F274: $ 53,860.00
E275: M.C. VENDEDOR | F275: $ 1,418,612.00
E276: SIN DINERO | F276: $ 1,025,712.00
E277: DEVOLUCION | F277: $ 2,167,797.00
E278: CERRADO | F278: $ 1,085,951.00
E279: LOGISTICA | F279: $ 895,640.00
E280: TOTAL | F280: $ 6,888,658.00
E283: RESUMEN POR VENDEDOR | F283: MARCELO
...

Sheet JULIO
A1: FALTANTE DE MERCADERIA JULIO 2026
A2: FECHA | B2: CLIENTE | C2: VENDEDOR | D2: COD-ART | E2: ARTICULO | F2: MOTIVO | G2: CANTIDAD | H2: PRECIO | I2: TOTAL
A3: 46205 | B3: URUEÑA FRANCISCO | C3: MARCELO | D3: 483 | E3: CABALLO PREMIUM X 30 KG | F3: M.C. VENDEDOR | G3: 30 | H3: $ 14,514.00 | I3: $ 435,420.00
A4: 46205 | B4: URUEÑA FRANCISCO | C4: MARCELO | D4: 722 | E4: POLENTA | F4: SIN DINERO | G4: 50 | H4: $ 739.00 | I4: $ 36,950.00
A5: 46205 | B5: URUEÑA FRANCISCO | C5: MARCELO | D5: 57 | E5: PONEDORA POSTURA X 40 KG | F5: SIN DINERO | G5: 3 | H5: $ 18,571.00 | I5: $ 55,713.00
A6: 46205 | B6: JUAREZ FEDERICO | C6: MARCELO | D6: 111 | E6: TIERNITO CARNE x 21 KG | F6: DEVOLUCION | G6: 5 | H6: $ 35,345.00 | I6: $ 176,725.00
A7: 46205 | B7: RENGEL FERNANDO | C7: MARCELO | D7: 458 | E7: GIRASOL GRANDE | F7: M.C. VENDEDOR | G7: 20 | H7: $ 1,787.00 | I7: $ 35,740.00
A8: 46206 | B8: BUSTOS LUIS | C8: MARCELO | D8: 232 | E8: EXACT PREMIUM ADULTO X 18K | F8: M.C. DEPOSITO S. | G8: 3 | H8: $ 26,652.00 | I8: $ 79,956.00
A9: 46207 | B9: IBAÑEZ NANCY | C9: MARCELO | D9: 10 | E9: PAJARO 4 mm x 25 Kg - GANAVE | F9: DEVOLUCION | G9: 1 | H9: $ 49,620.00 | I9: $ 49,620.00
A10: 46207 | B10: IBAÑEZ NANCY | C10: MARCELO | D10: 169 | E10: COMPLETE PERRO ADULTO RAZA MED Y GDE X 20KG | F10: DEVOLUCION | G10: 1 | H10: $ 54,536.00 | I10: $ 54,536.00
A11: 46207 | B11: GUERRA JUAN | C11: MARCELO | D11: 476 | E11: MAIZ QUEBRADO FINO X 30 KG | F11: DEVOLUCION | G11: 3 | H11: $ 12,130.00 | I11: $ 36,390.00
A12: 46207 | B12: GUERRA JUAN | C12: MARCELO | D12: 477 | E12: MAIZ QUEBRADO MEDIANO X 30 KG | F12: DEVOLUCION | G12: 10 | H12: $ 12,130.00 | I12: $ 121,300.00
A13: 46209 | B13: ERAZO VICTOR | C13: JULIO | D13: 507 | E13: BICARBONATO | F13: M.C. DEPOSITO E. | G13: 5 | H13: $ 3,450.00 | I13: $ 17,250.00
A14: 46209 | B14: MAZZONE MARIA | C14: MARCELO | D14: 482 | E14: MEZCLA FINA ESPECIAL (CARDENAL) | F14: DEVOLUCION | G14: 30 | H14: $ 744.00 | I14: $ 22,320.00
... A28: 46210 | B28: BRITO FRANCO | C28: MARCELO | D28: 130 | E28: GRAN CAMPEON AD ROJO Carne y Pollo X 21 KG | F28: M.C. VENDEDOR | G28: 2 | H28: $ 27,424.00 | I28: $ 54,848.00
A29: 46211 | B29: ALBORNOZ PALMIRA | C29: MARCELO | D29: 453 | E29: AVENA FORRAJERA X KG | F29: DEVOLUCION | G29: 300 | H29: 517 | I29: =SUM(H29*G29) -> 155100
A30: 46211 | B30: ARRIETA ARIEL | C30: MARCELO | D30: 995 | E30: PIEDRAS SANITARIAS MI NINO 12,5 | F30: DEVOLUCION | G30: 20 | H30: 5429 | I30: =SUM(H30*G30) -> 108580
A31: 46211 | B31: BRITO BRAHIAN | C31: MARCELO | D31: 614 | E31: PASAS SIN SEMILLA | F31: DEVOLUCION | G31: 5 | H31: 4812 | I31: =SUM(H31*G31) -> 24060
E32: #N/D | I32: =SUM(H32*G32) -> 0
E33: #N/D | I33: =SUM(H33*G33) -> 0
E34: #N/D | I34: =SUM(H34*G34) -> 0
E35: #N/D | I35: =SUM(H35*G35) -> 0
E36: #N/D | I36: =SUM(H36*G36) -> 0
E37: #N/D | I37: =SUM(H37*G37) -> 0
E38: #N/D | I38: =SUM(H38*G38) -> 0
E39: #N/D | I39: =SUM(H39*G39) -> 0
E40: #N/D | I40: =SUM(H40*G40) -> 0
E41: #N/D | I41: =SUM(H41*G41) -> 0
E42: #N/D | I42: =SUM(H42*G42) -> 0
E43: #N/D | I43: =SUM(H43*G43) -> 0
... E107: #N/D | I107: =SUM(H107*G107) -> 0
H108: TOTAL | I108: $ 1,384,169.0
E109: RESUMEN
E110: M.C. DEPOSITO S. | F110: $ 79,956.00
E111: M.C. DEPOSITO E. | F111: $ 68,975.00
E112: M.C. VENDEDOR | F112: $ 511,044.00
E113: SIN DINERO | F113: $ 92,663.00
E114: DEVOLUCION | F114: $ 631,531.00
E115: CERRADO | F115: $ -
E116: LOGISTICA | F116: $ -
...

Sheet vendedores
A1: CAUSALES REBOTES JULIO
A7: VENDEDOR | B7: JULIO | E7: VENDEDOR | F7: DARIO
A9: CAUSA | B9: TOTAL | E9: CAUSA | F9: TOTAL
A10: CERRADO | B10: 98790 | E10: CERRADO | F10: 88713
A11: DEVOLUCION | B11: 422183 | E11: DEVOLUCION | F11: 144447
A12: FALTO | B12: 175175 | E12: FALTO | F12: 267839
A13: M.C DEPOSITO | B13: 201975 | E13: M.C DEPOSITO | F13: 4420
A14: SIN DINERO | B14: 129432 | E14: Total general | F14: 505419
A15: Total general | B15: 1027555
A21: VENDEDOR | B21: MARCELO | E21: VENDEDOR | F21: SEBASTIAN
A23: CAUSA | B23: TOTAL | E23: CAUSA | F23: TOTAL
A24: CERRADO | B24: 905614 | E24: CERRADO | F24: 40316
A25: DEVOLUCION | B25: 664627 | E25: DEVOLUCION | F25: 28006
A26: FALTO | B26: 463307 | E26: M.C DEPOSITO | F26: 19314
A27: M.C DEPOSITO | B27: 193840 | E27: Total general | F27: 87636
A28: M.C VENDEDOR | B28: 612198
A29: Total general | B29: 2839586
E31: VENDEDOR | F31: BRAIAN
E33: CAUSA | F33: TOTAL
E34: DEVOLUCION | F34: 469307
E35: FALTO | F35: 49866
E36: SIN DINERO | F36: 504391
E37: Total general | F37: 1023564

Sheet Hoja4
A2: VENDEDOR | B2: BRAIAN
A4: Etiquetas de fila | B4: Suma de TOTAL
A5: DEVOLUCION | B5: 469307
A6: FALTO | B6: 49866
A7: SIN DINERO | B7: 504391
A8: Total general | B8: 1023564

Sheet ARTICULO
A1: COD_ARTICU | B1: DESCRIPCIO
A2: 12202 | B2: CHUPETE CERDO
A3: 800 | B3: ANTIBIOTICO X 250 GR
A4: 801 | B4: ANTIBIOTICO X 500 GR
A5: 802 | B5: ANTIBIOTICO X KG
A6: 12601 | B6: ANTIVITAMINICO X 50 GR
A7: 12602 | B7: ANTIVITAMINICO X KG
A8: 803 | B8: BAÐERA PLASTICA N░ 1
A9: 804 | B9: BAÐERA PLASTICA N░ 2
A10: 805 | B10: BAÐERA PLASTICA N░ 3
A11: 806 | B11: BAÐERA PLASTICA N░ 4
A12: 807 | B12: BASE PLASTICA BEBEDERO
A13: 808 | B13: BEBEDERO CON ALETA N░ 1
... A1408: 373 | B1408: FRAC. ALMOHADITA LIMON NF 20 X 180GR
B1409: EXIBIDOR MANI KING
A1410: 619 | B1410: PASAS RUBIAS
A1411: 679 | B1411: PASTA DE MANI VITA + X350 X 12un
A1412: 234 | B1412: EXACT CRIADORES ADULTO X21
A1413: 235 | B1413: EXACT CRIADORES CACHORRO X15
A1414: 1016 | B1414: ARENA SANITARIA VITAL FUN X6K
A1415: 236 | B1415: EXACT CRIADORES GATO 10K
A1416: 232 | B1416: EXACT PREMIUM ADULTO X 18K
A1417: 685 | B1417: PASTA MANI NATURAL 4KG x 2U-Mani king
A1418: 689 | B1418: PASTA MANI NATURAL BORIS X 400G X12U
A1419: 692 | B1419: PASTA MANI DULCE BORIS X400 X12U
A1420: 119 | B1420: TIERNITO GATITO X10KG
A1421: 696 | B1421: MONKY BLANCA X 18ud
... A1428: 2014 | B1428: FRAC. FRITO C/SAL MARINA 12X200 GR

Sheet RESUMENES 25
A1: RESUMEN FALTANTES DE MERCADERIA 2026
A3: MES | B3: M.C. DEPOSITO | C3: M.C. VENDEDOR | D3: FALTO | E3: SIN DINERO | F3: DEVOLUCION | G3: CERRADO | H3: TOTAL
A4: ENERO | B4: 186091 | C4: 0 | D4: 371700 | E4: 340012 | F4: 5001716 | H4: =SUM(A4:G4) -> 5899519
A5: FEBRERO | B5: 858581 | C5: 1470178 | D5: 994702 | E5: 619623 | F5: 2940179 | G5: 605739 | H5: =SUM(A5:G5) -> 7489002
A6: MARZO | B6: 225552 | C6: 242819 | D6: 96381 | E6: 1083233 | F6: 2254330 | G6: 1347130 | H6: =SUM(A6:G6) -> 5249445
A7: ABRIL | H7: =SUM(A7:G7) -> 0
A8: MAYO | H8: =SUM(A8:G8) -> 0
A9: JUNIO | H9: =SUM(A9:G9) -> 0
A10: JULIO | H10: =SUM(A10:G10) -> 0
A11: AGOSTO | H11: =SUM(A11:G11) -> 0
A12: SEPTIEMBRE | H12: =SUM(A12:G12) -> 0
A13: OCTUBRE | H13: =SUM(A13:G13) -> 0
A14: MOVIEMBRE | H14: =SUM(A14:G14) -> 0
A15: DICIEMBRE | H15: =SUM(A15:G15) -> 0
G16: TOTAL | H16: =SUM(H3:H15) -> 18637966
